<!DOCTYPE html>
<html lang="en">
<head>
    <meta charset="UTF-8">
    <title>Title</title>
</head>
<body>

</body>
</html>
<script>
    //异步任务的管理 示例1
    var p1 = new Promise(function (resolve, reject) {
        var a  = 10;
        if(a == 10){
            resolve(a);
        }else{
            reject("a不等于10");
        }
    })
    p1.then(function (value) {
        console.log(value);
    }),function (error) {
        console.log(error);
    }
    //示例1 的 变形  先确定p3的状态  然后 才能确定p4的状态
    var p3 = new Promise(function (resolve, reject) {
        var a  = 10;
        if(a == 10){
            resolve(a);
        }else{
            reject("a不等于10");
        }
    })
    var p4 = new Promise(function (resolve, reject) {
        var b  = 10;
        if(b == 10){
            resolve(b);
        }else{
            reject("b不等于10");
        }
    })
    p3.then(function (value) {
        return p4;
    }).then(function (value) {
        console.log(value)
    })
//    异步任务管理  示例2
//    p5是一个Promise，3秒之后变为rejected。p6的状态在1秒之后改变，resolve方法返回的是p5。
//    由于p6返回的是另一个 Promise，导致p6自己的状态无效了，
//    由p5的状态决定p6的状态。所以，后面的then语句都变成针对后者（p5）。
//    又过了2秒，p5变为rejected，导致触发catch方法指定的回调函数。
    var p5 = new Promise(function (resolve, reject) {
        setTimeout(() => reject(new Error('fail')), 3000)
    })

    var p6 = new Promise(function (resolve, reject) {
        setTimeout(() => resolve(p5), 1000)
    })

    p6
        .then(result => console.log(result))
    .catch(error => console.log(error))
    // Error: fail
    //
    //
    //常见回调函数的写法
    function mission1 () {
//        //任务1的代码
//        return function mission2() {
//            //任务2的代码
//            return function mission3() {
//                //任务3的代码
//            }
//        }
//    }


        //promise的写法
        mission1.then(function () {
            //任务1
            return mission2
        }).then(function () {
            //任务2
            return mission3
        }).then(function () {
            //任务3
        })

        //catch  捕获错误
    var p1 = new Promise(function(resolve,reject){
     reject(new Error("我是个错误"));
    })
        p1.then(function () {

        }).catch(function (error) {

        })
</script>